Traceback (most recent call last):
  File "/home/danmuner/packages/anaconda3/lib/python3.9/site-packages/jupyter_cache/executors/utils.py", line 51, in single_nb_execution
    executenb(
  File "/home/danmuner/packages/anaconda3/lib/python3.9/site-packages/nbclient/client.py", line 1204, in execute
    return NotebookClient(nb=nb, resources=resources, km=km, **kwargs).execute()
  File "/home/danmuner/packages/anaconda3/lib/python3.9/site-packages/nbclient/util.py", line 84, in wrapped
    return just_run(coro(*args, **kwargs))
  File "/home/danmuner/packages/anaconda3/lib/python3.9/site-packages/nbclient/util.py", line 62, in just_run
    return loop.run_until_complete(coro)
  File "/home/danmuner/packages/anaconda3/lib/python3.9/asyncio/base_events.py", line 642, in run_until_complete
    return future.result()
  File "/home/danmuner/packages/anaconda3/lib/python3.9/site-packages/nbclient/client.py", line 663, in async_execute
    await self.async_execute_cell(
  File "/home/danmuner/packages/anaconda3/lib/python3.9/site-packages/nbclient/client.py", line 965, in async_execute_cell
    await self._check_raise_for_error(cell, cell_index, exec_reply)
  File "/home/danmuner/packages/anaconda3/lib/python3.9/site-packages/nbclient/client.py", line 862, in _check_raise_for_error
    raise CellExecutionError.from_cell_and_msg(cell, exec_reply_content)
nbclient.exceptions.CellExecutionError: An error occurred while executing the following cell:
------------------
#We'll use pandas and numpy for data manipulation
import pandas as pd
import numpy as np
#We use seaborn and matplotlib to plot the data
import seaborn as sns
import matplotlib.pyplot as plt 
#Library to connect with postgresql
import psycopg2

#Establish connection with server adminsql@az-postgresql-server host on azure as IaaS
conn_sql = psycopg2.connect(user = "adminsql@az-postgresql-server",
                            password = "CEdndm1246",
                            host = "az-postgresql-server.postgres.database.azure.com",
                            port = "5432",
                            database = "postgres")
------------------

[0;31m---------------------------------------------------------------------------[0m
[0;31mOperationalError[0m                          Traceback (most recent call last)
Input [0;32mIn [1][0m, in [0;36m<cell line: 11>[0;34m()[0m
[1;32m      8[0m [38;5;28;01mimport[39;00m [38;5;21;01mpsycopg2[39;00m
[1;32m     10[0m [38;5;66;03m#Establish connection with server adminsql@az-postgresql-server host on azure as IaaS[39;00m
[0;32m---> 11[0m conn_sql [38;5;241m=[39m [43mpsycopg2[49m[38;5;241;43m.[39;49m[43mconnect[49m[43m([49m[43muser[49m[43m [49m[38;5;241;43m=[39;49m[43m [49m[38;5;124;43m"[39;49m[38;5;124;43madminsql@az-postgresql-server[39;49m[38;5;124;43m"[39;49m[43m,[49m
[1;32m     12[0m [43m                            [49m[43mpassword[49m[43m [49m[38;5;241;43m=[39;49m[43m [49m[38;5;124;43m"[39;49m[38;5;124;43mCEdndm1246[39;49m[38;5;124;43m"[39;49m[43m,[49m
[1;32m     13[0m [43m                            [49m[43mhost[49m[43m [49m[38;5;241;43m=[39;49m[43m [49m[38;5;124;43m"[39;49m[38;5;124;43maz-postgresql-server.postgres.database.azure.com[39;49m[38;5;124;43m"[39;49m[43m,[49m
[1;32m     14[0m [43m                            [49m[43mport[49m[43m [49m[38;5;241;43m=[39;49m[43m [49m[38;5;124;43m"[39;49m[38;5;124;43m5432[39;49m[38;5;124;43m"[39;49m[43m,[49m
[1;32m     15[0m [43m                            [49m[43mdatabase[49m[43m [49m[38;5;241;43m=[39;49m[43m [49m[38;5;124;43m"[39;49m[38;5;124;43mpostgres[39;49m[38;5;124;43m"[39;49m[43m)[49m

File [0;32m~/packages/anaconda3/lib/python3.9/site-packages/psycopg2/__init__.py:127[0m, in [0;36mconnect[0;34m(dsn, connection_factory, cursor_factory, **kwargs)[0m
[1;32m    124[0m     [38;5;28;01mraise[39;00m [38;5;167;01mTypeError[39;00m([38;5;124m'[39m[38;5;124mmissing dsn and no parameters[39m[38;5;124m'[39m)
[1;32m    126[0m dsn [38;5;241m=[39m _ext[38;5;241m.[39mmake_dsn(dsn, [38;5;241m*[39m[38;5;241m*[39mkwargs)
[0;32m--> 127[0m conn [38;5;241m=[39m [43m_connect[49m[43m([49m[43mdsn[49m[43m,[49m[43m [49m[43mconnection_factory[49m[38;5;241;43m=[39;49m[43mconnection_factory[49m[43m,[49m[43m [49m[38;5;241;43m*[39;49m[38;5;241;43m*[39;49m[43mkwasync[49m[43m)[49m
[1;32m    128[0m [38;5;28;01mif[39;00m cursor_factory [38;5;129;01mis[39;00m [38;5;129;01mnot[39;00m [38;5;28;01mNone[39;00m:
[1;32m    129[0m     conn[38;5;241m.[39mcursor_factory [38;5;241m=[39m cursor_factory

[0;31mOperationalError[0m: could not translate host name "az-postgresql-server.postgres.database.azure.com" to address: Name or service not known

OperationalError: could not translate host name "az-postgresql-server.postgres.database.azure.com" to address: Name or service not known


